<?xml version="1.0" ?>
<!-- =================================================================================== -->
<!-- |    This document was autogenerated by xacro from omni.urdf.xacro                | -->
<!-- |    EDITING THIS FILE BY HAND IS NOT RECOMMENDED                                 | -->
<!-- =================================================================================== -->
<robot name="open_base" xmlns:xacro="http://www.ros.org/wiki/xacro">
  <!-- lms100 -->
  <gazebo reference="laser_1">
    <sensor name="head_hokuyo_sensor" type="ray">
      <pose>0 0 0 0 0 0</pose>
      <visualize>true</visualize>
      <update_rate>50</update_rate>
      <ray>
        <scan>
          <horizontal>
            <samples>360</samples>
            <resolution>1</resolution>
            <min_angle>-1.570796</min_angle>
            <max_angle>1.570796</max_angle>
          </horizontal>
        </scan>
        <range>
          <min>0.10</min>
          <max>10.0</max>
          <resolution>0.01</resolution>
        </range>
        <noise>
          <type>gaussian</type>
          <!-- Noise parameters based on published spec for Hokuyo laser achieving 
						"+-30mm" accuracy at range < 10m. A mean of 0.0m and stddev of 0.01m will 
						put 99.7% of samples within 0.03m of the true reading. -->
          <mean>0.0</mean>
          <stddev>0.01</stddev>
        </noise>
      </ray>
      <plugin filename="libgazebo_ros_laser.so" name="gazebo_ros_head_hokuyo_controller">
        <topicName>/scan1</topicName>
        <frameName>/laser_1</frameName>
      </plugin>
    </sensor>
  </gazebo>
  <!-- lms100 -->
  <gazebo reference="laser_2">
    <sensor name="head_hokuyo_sensor" type="ray">
      <pose>0 0 0 0 0 0</pose>
      <visualize>true</visualize>
      <update_rate>50</update_rate>
      <ray>
        <scan>
          <horizontal>
            <samples>360</samples>
            <resolution>1</resolution>
            <min_angle>-1.570796</min_angle>
            <max_angle>1.570796</max_angle>
          </horizontal>
        </scan>
        <range>
          <min>0.10</min>
          <max>10.0</max>
          <resolution>0.01</resolution>
        </range>
        <noise>
          <type>gaussian</type>
          <!-- Noise parameters based on published spec for Hokuyo laser achieving 
						"+-30mm" accuracy at range < 10m. A mean of 0.0m and stddev of 0.01m will 
						put 99.7% of samples within 0.03m of the true reading. -->
          <mean>0.0</mean>
          <stddev>0.01</stddev>
        </noise>
      </ray>
      <plugin filename="libgazebo_ros_laser.so" name="gazebo_ros_head_hokuyo_controller">
        <topicName>/scan2</topicName>
        <frameName>/laser_2</frameName>
      </plugin>
    </sensor>
  </gazebo>
  <!-- ros control plugin 
<gazebo>
    <plugin name="gazebo_ros_control" filename="libgazebo_ros_control.so">
      <robotNamespace>/omnibase</robotNamespace>
      <legacyModeNS>true</legacyModeNS>
    </plugin>
  </gazebo> -->
  <!-- Planar move plugin -->
  <gazebo>
    <plugin filename="libgazebo_ros_planar_move.so" name="object_controller">
      <commandTopic>/omnibase/cmd_vel</commandTopic>
      <odometryTopic>/odom</odometryTopic>
      <odometryFrame>odom</odometryFrame>
      <odometryRate>20.0</odometryRate>
      <robotBaseFrame>base_link</robotBaseFrame>
    </plugin>
  </gazebo>
  <link name="origin_link"/>
  <link name="base_link">
    <inertial>
      <mass value="9.82868080625"/>
      <inertia ixx="0.06362454783" ixy="0" ixz="0" iyy="0.06362454783" iyz="0" izz="0.12331130197"/>
    </inertial>
    <visual>
      <geometry>
        <mesh filename="package://omni_description/mesh/base.stl" scale="5 5 5"/>
      </geometry>
      <material name="base_material">
        <color rgba="1 1 1 1"/>
      </material>
    </visual>
    <collision>
      <geometry>
        <mesh filename="package://omni_description/mesh/base.stl"/>
      </geometry>
    </collision>
  </link>
  <joint name="base_joint" type="fixed">
    <parent link="origin_link"/>
    <child link="base_link"/>
    <origin xyz="0 0 0.09525"/>
  </joint>
  <link name="rim_left_link">
    <inertial>
      <origin xyz="0 0 -0.000343"/>
      <mass value="1.0446975"/>
      <inertia ixx="0.0020740125" ixy="0" ixz="0" iyy="0.0020740125" iyz="0" izz="0.00293854062"/>
    </inertial>
    <visual>
      <geometry>
        <mesh filename="package://omni_description/mesh/rim.stl" scale="5 5 5"/>
      </geometry>
      <material name="rim_left_material">
        <color rgba="0.3 0 0 1"/>
      </material>
    </visual>
    <collision>
      <geometry>
        <mesh filename="package://omni_description/mesh/rim.stl"/>
      </geometry>
    </collision>
  </link>
  <joint name="rim_left_joint" type="continuous">
    <parent link="base_link"/>
    <child link="rim_left_link"/>
    <axis xyz="0 0 1"/>
    <origin rpy="1.570796326794896 0 1.047197551196597" xyz="-0.173205081 0.1 0"/>
  </joint>
  <link name="roller_e_rim_left_link">
    <inertial>
      <mass value="0.14230625"/>
      <inertia ixx="0.000079305" ixy="0" ixz="0" iyy="0.000079305" iyz="0" izz="0.00004614562"/>
    </inertial>
    <visual>
      <geometry>
        <mesh filename="package://omni_description/mesh/roller.stl" scale="5 5 5"/>
      </geometry>
      <material name="roller_material">
        <color rgba="0.1 0.1 0.1 1"/>
      </material>
    </visual>
    <collision>
      <geometry>
        <mesh filename="package://omni_description/mesh/roller.stl"/>
      </geometry>
    </collision>
  </link>
  <joint name="roller_e_rim_left_joint" type="continuous">
    <parent link="rim_left_link"/>
    <child link="roller_e_rim_left_link"/>
    <axis xyz="0 0 1"/>
    <origin rpy="-1.570796326794896 0 0" xyz="0.06775 0 0.0275"/>
  </joint>
  <link name="roller_ne_rim_left_link">
    <inertial>
      <mass value="0.14230625"/>
      <inertia ixx="0.000079305" ixy="0" ixz="0" iyy="0.000079305" iyz="0" izz="0.00004614562"/>
    </inertial>
    <visual>
      <geometry>
        <mesh filename="package://omni_description/mesh/roller.stl" scale="5 5 5"/>
      </geometry>
      <material name="roller_material">
        <color rgba="0.1 0.1 0.1 1"/>
      </material>
    </visual>
    <collision>
      <geometry>
        <mesh filename="package://omni_description/mesh/roller.stl"/>
      </geometry>
    </collision>
  </link>
  <joint name="roller_ne_rim_left_joint" type="continuous">
    <parent link="rim_left_link"/>
    <child link="roller_ne_rim_left_link"/>
    <axis xyz="0 0 1"/>
    <origin rpy="-1.570796326794896 0 0.7853981633974483" xyz="0.047906484 0.047906484 -0.0275"/>
  </joint>
  <link name="roller_n_rim_left_link">
    <inertial>
      <mass value="0.14230625"/>
      <inertia ixx="0.000079305" ixy="0" ixz="0" iyy="0.000079305" iyz="0" izz="0.00004614562"/>
    </inertial>
    <visual>
      <geometry>
        <mesh filename="package://omni_description/mesh/roller.stl" scale="5 5 5"/>
      </geometry>
      <material name="roller_material">
        <color rgba="0.1 0.1 0.1 1"/>
      </material>
    </visual>
    <collision>
      <geometry>
        <mesh filename="package://omni_description/mesh/roller.stl"/>
      </geometry>
    </collision>
  </link>
  <joint name="roller_n_rim_left_joint" type="continuous">
    <parent link="rim_left_link"/>
    <child link="roller_n_rim_left_link"/>
    <axis xyz="0 0 1"/>
    <origin rpy="-1.570796326794896 0 1.570796326794896" xyz="0 0.06775 0.0275"/>
  </joint>
  <link name="roller_nw_rim_left_link">
    <inertial>
      <mass value="0.14230625"/>
      <inertia ixx="0.000079305" ixy="0" ixz="0" iyy="0.000079305" iyz="0" izz="0.00004614562"/>
    </inertial>
    <visual>
      <geometry>
        <mesh filename="package://omni_description/mesh/roller.stl" scale="5 5 5"/>
      </geometry>
      <material name="roller_material">
        <color rgba="0.1 0.1 0.1 1"/>
      </material>
    </visual>
    <collision>
      <geometry>
        <mesh filename="package://omni_description/mesh/roller.stl"/>
      </geometry>
    </collision>
  </link>
  <joint name="roller_nw_rim_left_joint" type="continuous">
    <parent link="rim_left_link"/>
    <child link="roller_nw_rim_left_link"/>
    <axis xyz="0 0 1"/>
    <origin rpy="-1.570796326794896 0 2.356194490192345" xyz="-0.047906484 0.047906484 -0.0275"/>
  </joint>
  <link name="roller_w_rim_left_link">
    <inertial>
      <mass value="0.14230625"/>
      <inertia ixx="0.000079305" ixy="0" ixz="0" iyy="0.000079305" iyz="0" izz="0.00004614562"/>
    </inertial>
    <visual>
      <geometry>
        <mesh filename="package://omni_description/mesh/roller.stl" scale="5 5 5"/>
      </geometry>
      <material name="roller_material">
        <color rgba="0.1 0.1 0.1 1"/>
      </material>
    </visual>
    <collision>
      <geometry>
        <mesh filename="package://omni_description/mesh/roller.stl"/>
      </geometry>
    </collision>
  </link>
  <joint name="roller_w_rim_left_joint" type="continuous">
    <parent link="rim_left_link"/>
    <child link="roller_w_rim_left_link"/>
    <axis xyz="0 0 1"/>
    <origin rpy="-1.570796326794896 0 3.141592653589793" xyz="-0.06775 0 0.0275"/>
  </joint>
  <link name="roller_sw_rim_left_link">
    <inertial>
      <mass value="0.14230625"/>
      <inertia ixx="0.000079305" ixy="0" ixz="0" iyy="0.000079305" iyz="0" izz="0.00004614562"/>
    </inertial>
    <visual>
      <geometry>
        <mesh filename="package://omni_description/mesh/roller.stl" scale="5 5 5"/>
      </geometry>
      <material name="roller_material">
        <color rgba="0.1 0.1 0.1 1"/>
      </material>
    </visual>
    <collision>
      <geometry>
        <mesh filename="package://omni_description/mesh/roller.stl"/>
      </geometry>
    </collision>
  </link>
  <joint name="roller_sw_rim_left_joint" type="continuous">
    <parent link="rim_left_link"/>
    <child link="roller_sw_rim_left_link"/>
    <axis xyz="0 0 1"/>
    <origin rpy="-1.570796326794896 0 -2.356194490192345" xyz="-0.047906484 -0.047906484 -0.0275"/>
  </joint>
  <link name="roller_s_rim_left_link">
    <inertial>
      <mass value="0.14230625"/>
      <inertia ixx="0.000079305" ixy="0" ixz="0" iyy="0.000079305" iyz="0" izz="0.00004614562"/>
    </inertial>
    <visual>
      <geometry>
        <mesh filename="package://omni_description/mesh/roller.stl" scale="5 5 5"/>
      </geometry>
      <material name="roller_material">
        <color rgba="0.1 0.1 0.1 1"/>
      </material>
    </visual>
    <collision>
      <geometry>
        <mesh filename="package://omni_description/mesh/roller.stl"/>
      </geometry>
    </collision>
  </link>
  <joint name="roller_s_rim_left_joint" type="continuous">
    <parent link="rim_left_link"/>
    <child link="roller_s_rim_left_link"/>
    <axis xyz="0 0 1"/>
    <origin rpy="-1.570796326794896 0 -1.570796326794896" xyz="0 -0.06775 0.0275"/>
  </joint>
  <link name="roller_se_rim_left_link">
    <inertial>
      <mass value="0.14230625"/>
      <inertia ixx="0.000079305" ixy="0" ixz="0" iyy="0.000079305" iyz="0" izz="0.00004614562"/>
    </inertial>
    <visual>
      <geometry>
        <mesh filename="package://omni_description/mesh/roller.stl" scale="5 5 5"/>
      </geometry>
      <material name="roller_material">
        <color rgba="0.1 0.1 0.1 1"/>
      </material>
    </visual>
    <collision>
      <geometry>
        <mesh filename="package://omni_description/mesh/roller.stl"/>
      </geometry>
    </collision>
  </link>
  <joint name="roller_se_rim_left_joint" type="continuous">
    <parent link="rim_left_link"/>
    <child link="roller_se_rim_left_link"/>
    <axis xyz="0 0 1"/>
    <origin rpy="-1.570796326794896 0 -0.7853981633974483" xyz="0.047906484 -0.047906484 -0.0275"/>
  </joint>
  <transmission name="rim_left_transmission">
    <type>transmission_interface/SimpleTransmission</type>
    <joint name="rim_left_joint">
      <hardwareInterface>EffortJointInterface</hardwareInterface>
    </joint>
    <actuator name="rim_left_motor">
      <hardwareInterface>EffortJointInterface</hardwareInterface>
      <mechanicalReduction>1</mechanicalReduction>
    </actuator>
  </transmission>
  <link name="rim_back_link">
    <inertial>
      <origin xyz="0 0 -0.000343"/>
      <mass value="1.0446975"/>
      <inertia ixx="0.0020740125" ixy="0" ixz="0" iyy="0.0020740125" iyz="0" izz="0.00293854062"/>
    </inertial>
    <visual>
      <geometry>
        <mesh filename="package://omni_description/mesh/rim.stl" scale="5 5 5"/>
      </geometry>
      <material name="rim_back_material">
        <color rgba="0 0.3 0 1"/>
      </material>
    </visual>
    <collision>
      <geometry>
        <mesh filename="package://omni_description/mesh/rim.stl"/>
      </geometry>
    </collision>
  </link>
  <joint name="rim_back_joint" type="continuous">
    <parent link="base_link"/>
    <child link="rim_back_link"/>
    <axis xyz="0 0 1"/>
    <origin rpy="1.570796326794896 0 3.141592653589793" xyz="0 -0.2 0"/>
  </joint>
  <link name="roller_e_rim_back_link">
    <inertial>
      <mass value="0.14230625"/>
      <inertia ixx="0.000079305" ixy="0" ixz="0" iyy="0.000079305" iyz="0" izz="0.00004614562"/>
    </inertial>
    <visual>
      <geometry>
        <mesh filename="package://omni_description/mesh/roller.stl" scale="5 5 5"/>
      </geometry>
      <material name="roller_material">
        <color rgba="0.1 0.1 0.1 1"/>
      </material>
    </visual>
    <collision>
      <geometry>
        <mesh filename="package://omni_description/mesh/roller.stl"/>
      </geometry>
    </collision>
  </link>
  <joint name="roller_e_rim_back_joint" type="continuous">
    <parent link="rim_back_link"/>
    <child link="roller_e_rim_back_link"/>
    <axis xyz="0 0 1"/>
    <origin rpy="-1.570796326794896 0 0" xyz="0.06775 0 0.0275"/>
  </joint>
  <link name="roller_ne_rim_back_link">
    <inertial>
      <mass value="0.14230625"/>
      <inertia ixx="0.000079305" ixy="0" ixz="0" iyy="0.000079305" iyz="0" izz="0.00004614562"/>
    </inertial>
    <visual>
      <geometry>
        <mesh filename="package://omni_description/mesh/roller.stl" scale="5 5 5"/>
      </geometry>
      <material name="roller_material">
        <color rgba="0.1 0.1 0.1 1"/>
      </material>
    </visual>
    <collision>
      <geometry>
        <mesh filename="package://omni_description/mesh/roller.stl"/>
      </geometry>
    </collision>
  </link>
  <joint name="roller_ne_rim_back_joint" type="continuous">
    <parent link="rim_back_link"/>
    <child link="roller_ne_rim_back_link"/>
    <axis xyz="0 0 1"/>
    <origin rpy="-1.570796326794896 0 0.7853981633974483" xyz="0.047906484 0.047906484 -0.0275"/>
  </joint>
  <link name="roller_n_rim_back_link">
    <inertial>
      <mass value="0.14230625"/>
      <inertia ixx="0.000079305" ixy="0" ixz="0" iyy="0.000079305" iyz="0" izz="0.00004614562"/>
    </inertial>
    <visual>
      <geometry>
        <mesh filename="package://omni_description/mesh/roller.stl" scale="5 5 5"/>
      </geometry>
      <material name="roller_material">
        <color rgba="0.1 0.1 0.1 1"/>
      </material>
    </visual>
    <collision>
      <geometry>
        <mesh filename="package://omni_description/mesh/roller.stl"/>
      </geometry>
    </collision>
  </link>
  <joint name="roller_n_rim_back_joint" type="continuous">
    <parent link="rim_back_link"/>
    <child link="roller_n_rim_back_link"/>
    <axis xyz="0 0 1"/>
    <origin rpy="-1.570796326794896 0 1.570796326794896" xyz="0 0.06775 0.0275"/>
  </joint>
  <link name="roller_nw_rim_back_link">
    <inertial>
      <mass value="0.14230625"/>
      <inertia ixx="0.000079305" ixy="0" ixz="0" iyy="0.000079305" iyz="0" izz="0.00004614562"/>
    </inertial>
    <visual>
      <geometry>
        <mesh filename="package://omni_description/mesh/roller.stl" scale="5 5 5"/>
      </geometry>
      <material name="roller_material">
        <color rgba="0.1 0.1 0.1 1"/>
      </material>
    </visual>
    <collision>
      <geometry>
        <mesh filename="package://omni_description/mesh/roller.stl"/>
      </geometry>
    </collision>
  </link>
  <joint name="roller_nw_rim_back_joint" type="continuous">
    <parent link="rim_back_link"/>
    <child link="roller_nw_rim_back_link"/>
    <axis xyz="0 0 1"/>
    <origin rpy="-1.570796326794896 0 2.356194490192345" xyz="-0.047906484 0.047906484 -0.0275"/>
  </joint>
  <link name="roller_w_rim_back_link">
    <inertial>
      <mass value="0.14230625"/>
      <inertia ixx="0.000079305" ixy="0" ixz="0" iyy="0.000079305" iyz="0" izz="0.00004614562"/>
    </inertial>
    <visual>
      <geometry>
        <mesh filename="package://omni_description/mesh/roller.stl" scale="5 5 5"/>
      </geometry>
      <material name="roller_material">
        <color rgba="0.1 0.1 0.1 1"/>
      </material>
    </visual>
    <collision>
      <geometry>
        <mesh filename="package://omni_description/mesh/roller.stl"/>
      </geometry>
    </collision>
  </link>
  <joint name="roller_w_rim_back_joint" type="continuous">
    <parent link="rim_back_link"/>
    <child link="roller_w_rim_back_link"/>
    <axis xyz="0 0 1"/>
    <origin rpy="-1.570796326794896 0 3.141592653589793" xyz="-0.06775 0 0.0275"/>
  </joint>
  <link name="roller_sw_rim_back_link">
    <inertial>
      <mass value="0.14230625"/>
      <inertia ixx="0.000079305" ixy="0" ixz="0" iyy="0.000079305" iyz="0" izz="0.00004614562"/>
    </inertial>
    <visual>
      <geometry>
        <mesh filename="package://omni_description/mesh/roller.stl" scale="5 5 5"/>
      </geometry>
      <material name="roller_material">
        <color rgba="0.1 0.1 0.1 1"/>
      </material>
    </visual>
    <collision>
      <geometry>
        <mesh filename="package://omni_description/mesh/roller.stl"/>
      </geometry>
    </collision>
  </link>
  <joint name="roller_sw_rim_back_joint" type="continuous">
    <parent link="rim_back_link"/>
    <child link="roller_sw_rim_back_link"/>
    <axis xyz="0 0 1"/>
    <origin rpy="-1.570796326794896 0 -2.356194490192345" xyz="-0.047906484 -0.047906484 -0.0275"/>
  </joint>
  <link name="roller_s_rim_back_link">
    <inertial>
      <mass value="0.14230625"/>
      <inertia ixx="0.000079305" ixy="0" ixz="0" iyy="0.000079305" iyz="0" izz="0.00004614562"/>
    </inertial>
    <visual>
      <geometry>
        <mesh filename="package://omni_description/mesh/roller.stl" scale="5 5 5"/>
      </geometry>
      <material name="roller_material">
        <color rgba="0.1 0.1 0.1 1"/>
      </material>
    </visual>
    <collision>
      <geometry>
        <mesh filename="package://omni_description/mesh/roller.stl"/>
      </geometry>
    </collision>
  </link>
  <joint name="roller_s_rim_back_joint" type="continuous">
    <parent link="rim_back_link"/>
    <child link="roller_s_rim_back_link"/>
    <axis xyz="0 0 1"/>
    <origin rpy="-1.570796326794896 0 -1.570796326794896" xyz="0 -0.06775 0.0275"/>
  </joint>
  <link name="roller_se_rim_back_link">
    <inertial>
      <mass value="0.14230625"/>
      <inertia ixx="0.000079305" ixy="0" ixz="0" iyy="0.000079305" iyz="0" izz="0.00004614562"/>
    </inertial>
    <visual>
      <geometry>
        <mesh filename="package://omni_description/mesh/roller.stl" scale="5 5 5"/>
      </geometry>
      <material name="roller_material">
        <color rgba="0.1 0.1 0.1 1"/>
      </material>
    </visual>
    <collision>
      <geometry>
        <mesh filename="package://omni_description/mesh/roller.stl"/>
      </geometry>
    </collision>
  </link>
  <joint name="roller_se_rim_back_joint" type="continuous">
    <parent link="rim_back_link"/>
    <child link="roller_se_rim_back_link"/>
    <axis xyz="0 0 1"/>
    <origin rpy="-1.570796326794896 0 -0.7853981633974483" xyz="0.047906484 -0.047906484 -0.0275"/>
  </joint>
  <transmission name="rim_back_transmission">
    <type>transmission_interface/SimpleTransmission</type>
    <joint name="rim_back_joint">
      <hardwareInterface>EffortJointInterface</hardwareInterface>
    </joint>
    <actuator name="rim_back_motor">
      <hardwareInterface>EffortJointInterface</hardwareInterface>
      <mechanicalReduction>1</mechanicalReduction>
    </actuator>
  </transmission>
  <link name="rim_right_link">
    <inertial>
      <origin xyz="0 0 -0.000343"/>
      <mass value="1.0446975"/>
      <inertia ixx="0.0020740125" ixy="0" ixz="0" iyy="0.0020740125" iyz="0" izz="0.00293854062"/>
    </inertial>
    <visual>
      <geometry>
        <mesh filename="package://omni_description/mesh/rim.stl" scale="5 5 5"/>
      </geometry>
      <material name="rim_right_material">
        <color rgba="0 0 0.3 1"/>
      </material>
    </visual>
    <collision>
      <geometry>
        <mesh filename="package://omni_description/mesh/rim.stl"/>
      </geometry>
    </collision>
  </link>
  <joint name="rim_right_joint" type="continuous">
    <parent link="base_link"/>
    <child link="rim_right_link"/>
    <axis xyz="0 0 1"/>
    <origin rpy="1.570796326794896 0 -1.047197551196597" xyz="0.173205081 0.1 0"/>
  </joint>
  <link name="roller_e_rim_right_link">
    <inertial>
      <mass value="0.14230625"/>
      <inertia ixx="0.000079305" ixy="0" ixz="0" iyy="0.000079305" iyz="0" izz="0.00004614562"/>
    </inertial>
    <visual>
      <geometry>
        <mesh filename="package://omni_description/mesh/roller.stl" scale="5 5 5"/>
      </geometry>
      <material name="roller_material">
        <color rgba="0.1 0.1 0.1 1"/>
      </material>
    </visual>
    <collision>
      <geometry>
        <mesh filename="package://omni_description/mesh/roller.stl"/>
      </geometry>
    </collision>
  </link>
  <joint name="roller_e_rim_right_joint" type="continuous">
    <parent link="rim_right_link"/>
    <child link="roller_e_rim_right_link"/>
    <axis xyz="0 0 1"/>
    <origin rpy="-1.570796326794896 0 0" xyz="0.06775 0 0.0275"/>
  </joint>
  <link name="roller_ne_rim_right_link">
    <inertial>
      <mass value="0.14230625"/>
      <inertia ixx="0.000079305" ixy="0" ixz="0" iyy="0.000079305" iyz="0" izz="0.00004614562"/>
    </inertial>
    <visual>
      <geometry>
        <mesh filename="package://omni_description/mesh/roller.stl" scale="5 5 5"/>
      </geometry>
      <material name="roller_material">
        <color rgba="0.1 0.1 0.1 1"/>
      </material>
    </visual>
    <collision>
      <geometry>
        <mesh filename="package://omni_description/mesh/roller.stl"/>
      </geometry>
    </collision>
  </link>
  <joint name="roller_ne_rim_right_joint" type="continuous">
    <parent link="rim_right_link"/>
    <child link="roller_ne_rim_right_link"/>
    <axis xyz="0 0 1"/>
    <origin rpy="-1.570796326794896 0 0.7853981633974483" xyz="0.047906484 0.047906484 -0.0275"/>
  </joint>
  <link name="roller_n_rim_right_link">
    <inertial>
      <mass value="0.14230625"/>
      <inertia ixx="0.000079305" ixy="0" ixz="0" iyy="0.000079305" iyz="0" izz="0.00004614562"/>
    </inertial>
    <visual>
      <geometry>
        <mesh filename="package://omni_description/mesh/roller.stl" scale="5 5 5"/>
      </geometry>
      <material name="roller_material">
        <color rgba="0.1 0.1 0.1 1"/>
      </material>
    </visual>
    <collision>
      <geometry>
        <mesh filename="package://omni_description/mesh/roller.stl"/>
      </geometry>
    </collision>
  </link>
  <joint name="roller_n_rim_right_joint" type="continuous">
    <parent link="rim_right_link"/>
    <child link="roller_n_rim_right_link"/>
    <axis xyz="0 0 1"/>
    <origin rpy="-1.570796326794896 0 1.570796326794896" xyz="0 0.06775 0.0275"/>
  </joint>
  <link name="roller_nw_rim_right_link">
    <inertial>
      <mass value="0.14230625"/>
      <inertia ixx="0.000079305" ixy="0" ixz="0" iyy="0.000079305" iyz="0" izz="0.00004614562"/>
    </inertial>
    <visual>
      <geometry>
        <mesh filename="package://omni_description/mesh/roller.stl" scale="5 5 5"/>
      </geometry>
      <material name="roller_material">
        <color rgba="0.1 0.1 0.1 1"/>
      </material>
    </visual>
    <collision>
      <geometry>
        <mesh filename="package://omni_description/mesh/roller.stl"/>
      </geometry>
    </collision>
  </link>
  <joint name="roller_nw_rim_right_joint" type="continuous">
    <parent link="rim_right_link"/>
    <child link="roller_nw_rim_right_link"/>
    <axis xyz="0 0 1"/>
    <origin rpy="-1.570796326794896 0 2.356194490192345" xyz="-0.047906484 0.047906484 -0.0275"/>
  </joint>
  <link name="roller_w_rim_right_link">
    <inertial>
      <mass value="0.14230625"/>
      <inertia ixx="0.000079305" ixy="0" ixz="0" iyy="0.000079305" iyz="0" izz="0.00004614562"/>
    </inertial>
    <visual>
      <geometry>
        <mesh filename="package://omni_description/mesh/roller.stl" scale="5 5 5"/>
      </geometry>
      <material name="roller_material">
        <color rgba="0.1 0.1 0.1 1"/>
      </material>
    </visual>
    <collision>
      <geometry>
        <mesh filename="package://omni_description/mesh/roller.stl"/>
      </geometry>
    </collision>
  </link>
  <joint name="roller_w_rim_right_joint" type="continuous">
    <parent link="rim_right_link"/>
    <child link="roller_w_rim_right_link"/>
    <axis xyz="0 0 1"/>
    <origin rpy="-1.570796326794896 0 3.141592653589793" xyz="-0.06775 0 0.0275"/>
  </joint>
  <link name="roller_sw_rim_right_link">
    <inertial>
      <mass value="0.14230625"/>
      <inertia ixx="0.000079305" ixy="0" ixz="0" iyy="0.000079305" iyz="0" izz="0.00004614562"/>
    </inertial>
    <visual>
      <geometry>
        <mesh filename="package://omni_description/mesh/roller.stl" scale="5 5 5"/>
      </geometry>
      <material name="roller_material">
        <color rgba="0.1 0.1 0.1 1"/>
      </material>
    </visual>
    <collision>
      <geometry>
        <mesh filename="package://omni_description/mesh/roller.stl"/>
      </geometry>
    </collision>
  </link>
  <joint name="roller_sw_rim_right_joint" type="continuous">
    <parent link="rim_right_link"/>
    <child link="roller_sw_rim_right_link"/>
    <axis xyz="0 0 1"/>
    <origin rpy="-1.570796326794896 0 -2.356194490192345" xyz="-0.047906484 -0.047906484 -0.0275"/>
  </joint>
  <link name="roller_s_rim_right_link">
    <inertial>
      <mass value="0.14230625"/>
      <inertia ixx="0.000079305" ixy="0" ixz="0" iyy="0.000079305" iyz="0" izz="0.00004614562"/>
    </inertial>
    <visual>
      <geometry>
        <mesh filename="package://omni_description/mesh/roller.stl" scale="5 5 5"/>
      </geometry>
      <material name="roller_material">
        <color rgba="0.1 0.1 0.1 1"/>
      </material>
    </visual>
    <collision>
      <geometry>
        <mesh filename="package://omni_description/mesh/roller.stl"/>
      </geometry>
    </collision>
  </link>
  <joint name="roller_s_rim_right_joint" type="continuous">
    <parent link="rim_right_link"/>
    <child link="roller_s_rim_right_link"/>
    <axis xyz="0 0 1"/>
    <origin rpy="-1.570796326794896 0 -1.570796326794896" xyz="0 -0.06775 0.0275"/>
  </joint>
  <link name="roller_se_rim_right_link">
    <inertial>
      <mass value="0.14230625"/>
      <inertia ixx="0.000079305" ixy="0" ixz="0" iyy="0.000079305" iyz="0" izz="0.00004614562"/>
    </inertial>
    <visual>
      <geometry>
        <mesh filename="package://omni_description/mesh/roller.stl" scale="5 5 5"/>
      </geometry>
      <material name="roller_material">
        <color rgba="0.1 0.1 0.1 1"/>
      </material>
    </visual>
    <collision>
      <geometry>
        <mesh filename="package://omni_description/mesh/roller.stl"/>
      </geometry>
    </collision>
  </link>
  <joint name="roller_se_rim_right_joint" type="continuous">
    <parent link="rim_right_link"/>
    <child link="roller_se_rim_right_link"/>
    <axis xyz="0 0 1"/>
    <origin rpy="-1.570796326794896 0 -0.7853981633974483" xyz="0.047906484 -0.047906484 -0.0275"/>
  </joint>
  <transmission name="rim_right_transmission">
    <type>transmission_interface/SimpleTransmission</type>
    <joint name="rim_right_joint">
      <hardwareInterface>EffortJointInterface</hardwareInterface>
    </joint>
    <actuator name="rim_right_motor">
      <hardwareInterface>EffortJointInterface</hardwareInterface>
      <mechanicalReduction>1</mechanicalReduction>
    </actuator>
  </transmission>
  <!-- lms100 laser_1 -->
  <link name="laser_1">
    <inertial>
      <mass value="1e-5"/>
      <origin rpy="0 0 0" xyz="0 0 0"/>
      <inertia ixx="1e-6" ixy="0" ixz="0" iyy="1e-6" iyz="0" izz="1e-6"/>
    </inertial>
    <visual>
      <origin rpy="0 0 0" xyz="0 0 0"/>
      <geometry>
        <mesh filename="package://omni_description/mesh/lms100.dae"/>
      </geometry>
    </visual>
    <collision>
      <origin rpy="0 0 0" xyz="0 0 0"/>
      <geometry>
        <box size="0.1 0.1 0.1"/>
      </geometry>
    </collision>
  </link>
  <joint name="laser1_joint" type="fixed">
    <axis xyz="0 1 0"/>
    <origin rpy="0 0 0" xyz="0.05 0.0 0.05"/>
    <parent link="base_link"/>
    <child link="laser_1"/>
  </joint>
  <!-- lms100 laser_2 -->
  <link name="laser_2">
    <inertial>
      <mass value="1e-5"/>
      <origin rpy="0 0 0" xyz="0 0 0"/>
      <inertia ixx="1e-6" ixy="0" ixz="0" iyy="1e-6" iyz="0" izz="1e-6"/>
    </inertial>
    <visual>
      <origin rpy="0 0 0" xyz="0 0 0"/>
      <geometry>
        <mesh filename="package://omni_description/mesh/lms100.dae"/>
      </geometry>
    </visual>
    <collision>
      <origin rpy="0 0 0" xyz="0 0 0"/>
      <geometry>
        <box size="0.1 0.1 0.1"/>
      </geometry>
    </collision>
  </link>
  <joint name="laser2_joint" type="fixed">
    <axis xyz="0 1 0"/>
    <origin rpy="0 0 3.14159" xyz="-0.05 0 0.05"/>
    <parent link="base_link"/>
    <child link="laser_2"/>
  </joint>
</robot>
